## try-catch 조건

- try-catch에서 예외가 발생하지 않을 경우

   try 내에 있는 모든 문장이 실행되고 try-catch 문장 이후의 내용이 실행된다.

   (catch내 문장들은 실행 X)

- try-catch에서 예외가 발생하는 경우

try 내에서 예외가 발생한 이후의 문장들은 실행되지 않는다.

catch 내에 있는 문장은 반드시 실행되고, try- catch 문장 이후의 내용이 실행된다.

## try-catch의 변수 선언

- catch에서 사용하는 변수는 try 블록 앞에 선언해야 한다.

```java
// **올바른** 변수 지정 코드
package c.exception;

public class ExceptionVariable {
  public static void main(String[] args) {
    ExceptionVariable sample = new ExceptionVariable();
    sample.checkVariable();
    
    }
  public void checkVariable() {
    int [] intArray=new int[5];    <------------------try 문 밖에 변수 선언
    try {
      System.out.println(intArray[5]);
      } catch(Exception e) {
        System.out.println(intArray.length);
        }
      System.out.println("This code must run.");
    }
  }
```

```java
// **잘못된** 변수 지정 코드
package c.exception;

public class ExceptionVariable {
  public static void main(String[] args) {
    ExceptionVariable sample = new ExceptionVariable();
    sample.checkVariable();
    
    }
  public void checkVariable() {
    try {
      int [] intArray=new int[5]; <-----------try문 안에 변수 선언
      System.out.println(intArray[5]);
      } catch(Exception e) {
        System.out.println(intArray.length);
        }
      System.out.println("This code must run.");
    }
  }

intArray가 try 블록 안에서 선언되었기 때문에 
catch에서는 intArray가 누군지 모르기 때문에 에러 발생
```

## finally

- finally 블록은 예외 발생 여부와 상관 없이 실행
- 코드의 중복을 피하기 위해서 반드시 필요하다.

```java
// finally 블록 코드 사용
package c.exception;

public class ExceptionVariable {
  public static void main(String[] args) {
    ExceptionVariable sample = new ExceptionVariable();
    sample.checkVariable();
    
    }
  public void checkVariable() {
    int [] intArray=new int[5];    
    try {
      System.out.println(intArray[5]);
      } catch(Exception e) {
        System.out.println(intArray.length);
        } finally {           <-----------------fianlly 블록
      System.out.println("This code must run.");
          }
      }
  }
```

## 두 개 이상의 catch

- **try 다음에 오는 catch 블록은 1개 이상 올 수 있다.**
- **먼저 선언한 catch 블록의 예외 클래스가 다음에 선언한 catch 블록의 부모에 속하면, 자식에 속하는 catch 블록은 절대 실행될 일이 없으므로 컴파일 되지 않는다.**

```java
  public void checkVariable() {
    int [] intArray=new int[5];
    try {

      System.out.println(intArray[5]);  

      }  catch(Exception e){ <-------------------------부모 클래스
        System.out.println(intArray.length);
        }
         catch(NullPointerException e) { < ------------부모 클래스에 속하는 자식 클래스
        System.out.println( " NullPointerException occurred " );
        }
    }
  }

실행
컴파일 에러
```

- **하나의 try 블록에서 예외 발생하면 그 예외가 관련이 있는 catch 블록을 찾아서 실행**

NullPointerException 예외 : 아직 초기화 하지 않았거나 null된 객체에 있는 메소드를 호출하거나 처리하려고 할 때 발생하는 예외

ArrayIndexOutOfBoundsException 예외 : 배열에서 발생하는 예외

Exception 예외 :모든 예외의 부모클래스는 java.lang.Exception 클래스 이기 때문에 Exception 클래스로 catch 하는 것을  가장 아래에 추가할 것을 권장

마지막에 추가함으로써 예외들이 빠져 나가지 않게 묶어주는 것

```java
package c.exception;

public class ExceptionVariable {
  public static void main(String[] args) {
    ExceptionVariable sample = new ExceptionVariable();
    sample.checkVariable();
    
    }
  public void checkVariable() {
    int [] intArray=new int[5];
    try {

      System.out.println(intArray[5]);   <----------**배열**에서 예외 발생

      } catch(NullPointerException e) {
        System.out.println( " NullPointerException occurred " );
        }
        catch(ArrayIndexOutOfBoundsException e){
        System.out.println("ArrayIndexOutOfBoundsException occurred");
      } catch(Exception e){
        System.out.println(intArray.length);
        }
    }
  }

실행 값
ArrayIndexOutOfBoundsException occurred
```

```java
package c.exception;

public class ExceptionVariable {
  public static void main(String[] args) {
    ExceptionVariable sample = new ExceptionVariable();
    sample.checkVariable();
    
    }
  public void checkVariable() {
    int [] intArray=new int[5];
    try {
      intArray=null;       <----------    해당 객체가 null인지 확인하는 작업 먼저 수행
      System.out.println(intArray[5]);    ArrayIndexOutOfBoundsException 발생하기 전에
                                          NullPointerException 먼저 수행된 것 
      } catch(NullPointerException e) {
        System.out.println( " NullPointerException occurred " );
        }
        catch(ArrayIndexOutOfBoundsException e){
        System.out.println("ArrayIndexOutOfBoundsException occurred");
      } catch(Exception e){
        System.out.println(intArray.length);
        }
    }
  }

실행 값
NullPointerException occurred
```

## 예외의 종류는 세 가지

- **checked exception**
    - error, runtime exception(unchecked exception) 제외한 모든 에러
- **error**
    - 자바 프로그램 밖에서 발생한 예외
    - Error와 Exception으로 끝나는 오류의 가장 큰 차이는 프로그램 안에서 발생했는지, 밖에서 발생했는지 여부(프로그램이 멈추어 버리는지 계속 실행할 수 있는지 차이)
    - Error는 프로세스에 영향을 주고, Exception은 쓰레드에만 영향을 준다.
- **runtime exception 혹은 unchecked exception**
    - 예외가 발생할 것을 미리 감지하지 못했을 때 발생
    - RuntimeException을 확장한 예외들
    - 이 예외를 묶어주지 않는다고 해서 컴파일할 때 예외가 발생하지 않지만 실행시에는 발생할 가능성이 있다.
    - 호출하는 메소드에 try-catch로 묶어 주는 것이 좋다.

## java.lang.Throwable 클래스

- Exception과 Error는 OBject 클래스와 공통 부모 클래스로 Throwable클래스를 상속 받는다
    
    → 이렇게 상속 관계가 되어 있는 이유는 Exception, Error 클래스는 성격은 다르지만 동일한 이름의 메소드를 사용하여 처리할 수 있기 위함
    
    Throwable에 선언되어 있고, Exception 클래스에서 Overriding한 메소드 중 많이 쓰이는 메소드 3가지
    
    - **getMessage()**
        - 예외 메시지를 String 형태로 제공 받는다.
        
        ```java
        package c.exception;
        
        public class ThrowSample {
          public static void main(String[] args) {
            ThrowSample sample = new ThrowSample();
            sample.throwable();
            
            }
          public void throwable() {
            int [] intArray=new int[5];
            try {
              intArray=null;
              System.out.println(intArray[5]);
              } catch(Throwable t) {            <---------Throwable 클래스의 t 객체 생성
                System.out.println(t.getMessage());     <-------- t 객체 통해 
                                                                getMessage()메소드 호출
                }
            }
          }
        실행 값
        null
        ```
        
    - **toString()**
        - 예외 메시지를 String 형태로 제공 받는다.getMessage()보다 더 자세하게 예외 클래스 이름도 같이 제공한다.
            
            ```java
            package c.exception;
            
            public class ThrowSample {
              public static void main(String[] args) {
                ThrowSample sample = new ThrowSample();
                sample.throwable();
                
                }
              public void throwable() {
                int [] intArray=new int[5];
                try {
                  intArray=null;
                  System.out.println(intArray[5]);
                  } catch(Throwable t) {            <---------Throwable 클래스의 t 객체 생성
                    System.out.println(t.toString());     <-------- t 객체 통해 
                                                                    toSTring()메소드 호출
                    }
                }
              }
            실행 값
            null
            java.lang.NullPointerException
            ```
            
    
    - printStackTrace()
        - 가장 첫 줄에는 예외 메시지를 출력하고, 두 번째 줄부터는 예외가 발생하게 된 메소드들의 호출 관계(스택 트레이스)를 출력해준다.
        - 많은 양의 로그가 쌓이기 떄문에 개발할 때만 사용하는 것을 권고

## Throws

- 예외 발생시키는 방법
    - try블록 내에 throw라고 명시한 후 개발자가 예외 클래스의 객체를 생성 하거나 생성되어있는 객체 명시한다. 그러면 throw한 문장 이후에 있는 try블록 내의 문장들은 수행 되지 않고, catch블록으로 이동한다.
    - catch블록 중에 throw한 예외와 동일하거나 상속 관계에 있는 예외가 있다면 그 블록에서 예외를 처리할 수 있다.
    
    ```java
    package c.exception;
    
    public class ThrowSample {
      public static void main(String[] args) {
        ThrowSample sample = new ThrowSample();
        sample.throwException(13);
        
        }
      public void throwException(int number) {
        
        try {
          if(number>12) {
          throw new Exception("Number is over than 12");  <-------throw 명시 후 
                                                                   예외 클래스 객체 생성
          } 
          System.out.println("Number is "+number);
        } catch (Exception e) {
          e.printStackTrace();
          }
      }
    ```
    
- 발생한 예외의 catch문이 없다면 발생된 예외는 메소드 밖, 즉 예외가 발생된 메소드를 호출한 메소드로 던진다.
- 이렇게 선언하면, 예외가 발생했을 때 try-catch로 묶어주지 않아도 그 메소드를 호출한 메소드로 예외 처리를 위임한다.

```java
public void throwException(int number) throws Exception { <----호출한 메소드로 던진다.
    {
      if(number>12) {
      throw new Exception("Number is over than 12");
      } 
      System.out.println("Number is "+number);

  }
```

- 이 때 호출한 메소드를 try-catch로 묶어야 에러 발생하지 않는다.

```java
public class ThrowSample {
  public static void main(String[] args) {
    ThrowSample sample = new ThrowSample();
    sample.throwException(13);

   try {
    sample.throwsException(13);
    } catch(Exception e) { 
      ]
```

- throws 문장으로 컴파일 오류가 생겼을 경우 해결 방법
    - 호출한 메소드를 try-catch로 묶는다.
    - 호출한 메소드에서도 다시 throws 한다. (권장x)

catch문에서 로그에 남기는 등의 작업을 하고 예외를 throw를 이용하여 던져 주어야 문제가 발생한 정확한 원일을 찾을 수 있다.

임의의 예외 클래스 만들 때는 반드시 try-catch로 묶어줄 필요가 있을 경우에만 Exception 클래스를 확장한다.

일반적으로 실행 시 예외를 처리할 수 있는 경우에는 RuntimeException 클래스를 확장하는 것을 권장

catch문 내에 아무런 작업 없이 공백을 놔두면 예외 분석이 어려워지므로 꼭 로그 처리와 같은 예외 처리를 해줘야 한다.
